2019-09-07 10:55:44,742 -  nornir.core -     INFO -        run() - Running task 'my_task' with args {} on 2 hosts
2019-09-07 11:11:04,940 -  nornir.core -     INFO -        run() - Running task 'my_task' with args {} on 2 hosts
2019-09-07 11:11:04,945 - nornir.core.task -    ERROR -      start() - Host 'cisco4': task 'my_task' failed with traceback:
Traceback (most recent call last):
  File "/home/eweadon/VENV/py3_venv/local/lib/python3.6/site-packages/nornir/core/task.py", line 67, in start
    r = self.task(self, **self.params)
  File "ex4.py", line 7, in my_task
    time.sleep(random())
TypeError: 'module' object is not callable

2019-09-07 11:11:04,945 - nornir.core.task -    ERROR -      start() - Host 'cisco3': task 'my_task' failed with traceback:
Traceback (most recent call last):
  File "/home/eweadon/VENV/py3_venv/local/lib/python3.6/site-packages/nornir/core/task.py", line 67, in start
    r = self.task(self, **self.params)
  File "ex4.py", line 7, in my_task
    time.sleep(random())
TypeError: 'module' object is not callable

2019-09-07 11:13:00,208 -  nornir.core -     INFO -        run() - Running task 'my_task' with args {} on 2 hosts
2019-09-07 11:13:00,212 - nornir.core.task -    ERROR -      start() - Host 'cisco3': task 'my_task' failed with traceback:
Traceback (most recent call last):
  File "/home/eweadon/VENV/py3_venv/local/lib/python3.6/site-packages/nornir/core/task.py", line 67, in start
    r = self.task(self, **self.params)
  File "ex4.py", line 7, in my_task
    time.sleep(random())
TypeError: 'module' object is not callable

2019-09-07 11:13:00,213 - nornir.core.task -    ERROR -      start() - Host 'cisco4': task 'my_task' failed with traceback:
Traceback (most recent call last):
  File "/home/eweadon/VENV/py3_venv/local/lib/python3.6/site-packages/nornir/core/task.py", line 67, in start
    r = self.task(self, **self.params)
  File "ex4.py", line 7, in my_task
    time.sleep(random())
TypeError: 'module' object is not callable

2019-09-07 11:13:15,200 -  nornir.core -     INFO -        run() - Running task 'my_task' with args {} on 2 hosts
2019-09-07 11:13:15,204 - nornir.core.task -    ERROR -      start() - Host 'cisco3': task 'my_task' failed with traceback:
Traceback (most recent call last):
  File "/home/eweadon/VENV/py3_venv/local/lib/python3.6/site-packages/nornir/core/task.py", line 67, in start
    r = self.task(self, **self.params)
  File "/home/eweadon/nornir_class/wk1/ex4.py", line 7, in my_task
    time.sleep(random())
TypeError: 'module' object is not callable

2019-09-07 11:13:15,204 - nornir.core.task -    ERROR -      start() - Host 'cisco4': task 'my_task' failed with traceback:
Traceback (most recent call last):
  File "/home/eweadon/VENV/py3_venv/local/lib/python3.6/site-packages/nornir/core/task.py", line 67, in start
    r = self.task(self, **self.params)
  File "/home/eweadon/nornir_class/wk1/ex4.py", line 7, in my_task
    time.sleep(random())
TypeError: 'module' object is not callable

2019-09-07 11:17:15,161 -  nornir.core -     INFO -        run() - Running task 'my_task' with args {} on 2 hosts
2019-09-07 11:17:15,166 - nornir.core.task -    ERROR -      start() - Host 'cisco3': task 'my_task' failed with traceback:
Traceback (most recent call last):
  File "/home/eweadon/VENV/py3_venv/local/lib/python3.6/site-packages/nornir/core/task.py", line 67, in start
    r = self.task(self, **self.params)
  File "<ipython-input-4-0476e4c67cf9>", line 2, in my_task
    time.sleep(random())
TypeError: 'module' object is not callable

2019-09-07 11:17:15,166 - nornir.core.task -    ERROR -      start() - Host 'cisco4': task 'my_task' failed with traceback:
Traceback (most recent call last):
  File "/home/eweadon/VENV/py3_venv/local/lib/python3.6/site-packages/nornir/core/task.py", line 67, in start
    r = self.task(self, **self.params)
  File "<ipython-input-4-0476e4c67cf9>", line 2, in my_task
    time.sleep(random())
TypeError: 'module' object is not callable

2019-09-07 11:18:29,699 -  nornir.core -     INFO -        run() - Running task 'my_task' with args {} on 2 hosts
2019-09-07 11:21:02,894 -  nornir.core -     INFO -        run() - Running task 'my_task' with args {} on 2 hosts
2019-09-07 11:21:09,781 -  nornir.core -     INFO -        run() - Running task 'my_task' with args {} on 2 hosts
2019-09-07 11:22:02,578 -  nornir.core -     INFO -        run() - Running task 'my_task' with args {} on 2 hosts
2019-09-07 11:22:11,451 -  nornir.core -     INFO -        run() - Running task 'my_task' with args {} on 2 hosts
2019-09-07 11:22:16,138 -  nornir.core -     INFO -        run() - Running task 'my_task' with args {} on 2 hosts
2019-09-07 11:22:20,384 -  nornir.core -     INFO -        run() - Running task 'my_task' with args {} on 2 hosts
2019-09-07 11:25:18,345 -  nornir.core -     INFO -        run() - Running task 'my_task' with args {} on 2 hosts
2019-09-07 11:25:19,159 - nornir.core.task -    ERROR -      start() - Host 'cisco4': task 'my_task' failed with traceback:
Traceback (most recent call last):
  File "/home/eweadon/VENV/py3_venv/local/lib/python3.6/site-packages/nornir/core/task.py", line 67, in start
    r = self.task(self, **self.params)
  File "ex5.py", line 10, in my_task
    print(task.host.data.dns1)
AttributeError: 'dict' object has no attribute 'dns1'

2019-09-07 11:25:19,237 - nornir.core.task -    ERROR -      start() - Host 'cisco3': task 'my_task' failed with traceback:
Traceback (most recent call last):
  File "/home/eweadon/VENV/py3_venv/local/lib/python3.6/site-packages/nornir/core/task.py", line 67, in start
    r = self.task(self, **self.params)
  File "ex5.py", line 10, in my_task
    print(task.host.data.dns1)
AttributeError: 'dict' object has no attribute 'dns1'

2019-09-07 11:30:29,585 -  nornir.core -     INFO -        run() - Running task 'my_task' with args {} on 2 hosts
2019-09-07 11:34:16,554 -  nornir.core -     INFO -        run() - Running task 'my_task' with args {} on 2 hosts
2019-09-07 12:05:17,980 -  nornir.core -     INFO -        run() - Running task 'my_task' with args {} on 2 hosts
2019-09-07 12:09:06,076 -  nornir.core -     INFO -        run() - Running task 'my_task' with args {} on 2 hosts
2019-09-07 12:09:35,078 -  nornir.core -     INFO -        run() - Running task 'my_task' with args {} on 2 hosts
2019-09-07 12:10:00,727 -  nornir.core -     INFO -        run() - Running task 'my_task' with args {} on 2 hosts
